<?xml version="1.0"?>
<sdf version="1.10">
  <model name="robot_car" canonical_link="base_link">
    <!-- ======================== LINKS ======================== -->
    <!-- Base -->
    <link name="base_link">
      <pose relative_to="__model__">0 0 0 0 0 0</pose>
    </link>

    <!-- Chassis -->
    <link name="chassis">
      <pose relative_to="base_link">0 0 0.242 0 0 0</pose>
      <!-- Inertial -->
      <inertial>
        <mass>2.0</mass>
        <inertia>
          <ixx>0.126164</ixx>
          <ixy>0</ixy>
          <ixz>0</ixz>
          <iyy>0.416519</iyy>
          <iyz>0</iyz>
          <izz>0.481014</izz>
        </inertia>
      </inertial>
      <!-- Collision geometry -->
      <collision name="chassis_collision">
        <geometry>
          <box>
            <size>0.586 0.242 0.343</size>
          </box>
        </geometry>
      </collision>
      <!-- Visual geometry -->
      <visual name="chassis_visual">
        <pose>0 0 0 1.5707 0 1.5707</pose>
        <geometry>
          <mesh>
            <uri>package://robot/models/robot/meshes/shassis.obj</uri>
            <scale>0.505 0.505 0.505</scale>
          </mesh>
        </geometry>
      </visual>
    </link>

    <joint name="chassis_joint" type="fixed">
      <parent>base_link</parent>
      <child>chassis</child>
      <pose>0 0 0 0 0 0</pose>
    </joint>
    <link name='base_footprint'>
      <pose relative_to='base_link'>0 0 0 0 0 0</pose>
    </link>
    <joint name='base_footprint_joint' type='fixed'>
      <parent>base_link</parent>
      <child>base_footprint</child>
    </joint>
    <!-- Left wheel -->
    <link name="left_wheel">
      <pose relative_to="chassis">-0.182 0.191 -0.040 1.5707 0 0</pose>
      <inertial>
        <mass>0.07</mass>
        <inertia>
          <ixx>0.01556</ixx>
          <ixy>0.0</ixy>
          <ixz>0.0</ixz>
          <iyy>0.01556</iyy>
          <iyz>0.0</iyz>
          <izz>0.026244</izz>
        </inertia>
      </inertial>
      <collision name="left_wheel_collision">
        <geometry>
          <cylinder>
            <radius>0.162</radius>
            <length>0.121</length>
          </cylinder>
        </geometry>
      </collision>
      <visual name="left_wheel_visual">
        <pose>0 0 0.07 -1.5707 0 0</pose>
        <geometry>
          <mesh>
            <uri>package://robot/models/robot/meshes/wheel.obj</uri>
            <scale>0.202 0.202 0.202</scale>
          </mesh>
        </geometry>
      </visual>
    </link>

    <!-- Right wheel -->
    <link name="right_wheel">
      <pose relative_to="chassis">-0.182 -0.191 -0.040 -1.5707 0 0</pose>
      <inertial>
        <mass>0.07</mass>
        <inertia>
          <ixx>0.01556</ixx>
          <ixy>0.0</ixy>
          <ixz>0.0</ixz>
          <iyy>0.01556</iyy>
          <iyz>0.0</iyz>
          <izz>0.026244</izz>
        </inertia>
      </inertial>
      <collision name="right_wheel_collision">
        <geometry>
          <cylinder>
            <radius>0.162</radius>
            <length>0.121</length>
          </cylinder>
        </geometry>
      </collision>
      <visual name="right_wheel_visual">
        <pose>0 0 0.07 -1.5707 0 0</pose>
        <geometry>
          <mesh>
            <uri>package://robot/models/robot/meshes/wheel.obj</uri>
            <scale>0.202 0.202 0.202</scale>
          </mesh>
        </geometry>
      </visual>
    </link>

    <!-- Left front wheel -->
    <link name="left_front_wheel">
      <pose relative_to="chassis">0.182 0.191 -0.040 1.5707 0 0</pose>
      <inertial>
        <mass>0.07</mass>
        <inertia>
          <ixx>0.01556</ixx>
          <ixy>0.0</ixy>
          <ixz>0.0</ixz>
          <iyy>0.01556</iyy>
          <iyz>0.0</iyz>
          <izz>0.026244</izz>
        </inertia>
      </inertial>
      <collision name="left_front_wheel_collision">
        <geometry>
          <cylinder>
            <radius>0.162</radius>
            <length>0.121</length>
          </cylinder>
        </geometry>
      </collision>
      <visual name="left_front_wheel_visual">
        <pose>0 0 0.07 -1.5707 0 0</pose>
        <geometry>
          <mesh>
            <uri>package://robot/models/robot/meshes/wheel.obj</uri>
            <scale>0.202 0.202 0.202</scale>
          </mesh>
        </geometry>
      </visual>
    </link>

    <!-- Right front wheel -->
    <link name="right_front_wheel">
      <pose relative_to="chassis">0.182 -0.191 -0.040 -1.5707 0 0</pose>
      <inertial>
        <mass>0.07</mass>
        <inertia>
          <ixx>0.01556</ixx>
          <ixy>0.0</ixy>
          <ixz>0.0</ixz>
          <iyy>0.01556</iyy>
          <iyz>0.0</iyz>
          <izz>0.026244</izz>
        </inertia>
      </inertial>
      <collision name="right_front_wheel_collision">
        <geometry>
          <cylinder>
            <radius>0.162</radius>
            <length>0.121</length>
          </cylinder>
        </geometry>
      </collision>
      <visual name="right_front_wheel_visual">
        <pose>0 0 0.07 -1.5707 0 0</pose>
        <geometry>
          <mesh>
            <uri>package://robot/models/robot/meshes/wheel.obj</uri>
            <scale>0.202 0.202 0.202</scale>
          </mesh>
        </geometry>
      </visual>
    </link>

    <!-- ======================== SENSORS ======================== -->

    <!-- Camera sensor -->
    <link name="camera_body">
      <pose relative_to="chassis">0.3 0 0.05 0 0 0</pose>
      <inertial>
        <mass>0.1</mass>
        <inertia>
          <ixx>0.000166667</ixx>
          <iyy>0.000166667</iyy>
          <izz>0.000166667</izz>
        </inertia>
      </inertial>
      <collision name="collision">
        <geometry>
          <box>
            <size>0.05 0.05 0.05</size>
          </box>
        </geometry>
      </collision>
      <visual name="visual">
        <geometry>
          <box>
            <size>0.05 0.05 0.05</size>
          </box>
        </geometry>
      </visual>
      <sensor name="camera" type="camera">
        <camera>
          <optical_frame_id>camera</optical_frame_id>
          <horizontal_fov>1.047</horizontal_fov>
          <image>
            <width>320</width>
            <height>240</height>
          </image>
          <clip>
            <near>0.1</near>
            <far>100</far>
          </clip>
        </camera>
        <always_on>1</always_on>
        <update_rate>30</update_rate>
        <visualize>true</visualize>
        <topic>camera</topic>
      </sensor>
    </link>
    <link name = 'camera'>
      <pose relative_to='camera_body'>0.01 0 0 1.5708 3.141 1.5707</pose>
    </link>
    <joint name='camera_optical_joint' type='fixed'>
      <parent>camera_body</parent>
      <child>camera</child>
    </joint>
    <joint name="camera_joint" type="fixed">
      <parent>chassis</parent>
      <child>camera_body</child>
    </joint>

    <!-- GPS sensor -->
    <link name="gps_link">
      <pose relative_to="chassis">-0.1 0 0.32 0 0 0</pose>
      <inertial>
        <mass>0.1</mass>
        <inertia>
          <ixx>0.000166667</ixx>
          <iyy>0.000166667</iyy>
          <izz>0.000166667</izz>
        </inertia>
      </inertial>
      <collision name="collision">
        <geometry>
          <box>
            <size>0.01 0.01 0.01</size>
          </box>
        </geometry>
      </collision>
      <visual name="visual">
        <geometry>
          <box>
            <size>0.01 0.01 0.01</size>
          </box>
        </geometry>
      </visual>
      <sensor name="navsat_sensor" type="navsat">
        <always_on>1</always_on>
        <update_rate>30</update_rate>
        <topic>navsat</topic>
        <gz_frame_id>gps</gz_frame_id>
      </sensor>
    </link>
    <joint name="gps_joint" type="fixed">
      <parent>chassis</parent>
      <child>gps_link</child>
    </joint>

    <!-- Lidar sensor -->
    <link name="lidar">
      <pose relative_to="chassis">0.0 0.0 0.33 0 0 0</pose>
      <inertial>
        <mass>0.01</mass>
        <inertia>
          <ixx>0.000166667</ixx>
          <iyy>0.000166667</iyy>
          <izz>0.000166667</izz>
        </inertia>
      </inertial>
      <collision name="collision">
        <geometry>
          <box>
            <size>0.01 0.01 0.01</size>
          </box>
        </geometry>
      </collision>
      <visual name="visual">
        <geometry>
          <cylinder>
            <radius>0.05</radius>
            <length>0.05</length>
          </cylinder>
        </geometry>
      </visual>
      <sensor name="gpu_lidar" type="gpu_lidar">
        <pose relative_to="lidar">0 0 0.0 0 0 0</pose>
        <topic>scan</topic>
        <gz_frame_id>lidar</gz_frame_id>
        <update_rate>10</update_rate>
        <lidar>
          <scan>
            <horizontal>
              <samples>1081</samples>
              <resolution>1</resolution>
              <min_angle>-2.356</min_angle>
              <max_angle>2.356</max_angle>
            </horizontal>
          </scan>
          <range>
            <min>0.05</min>
            <max>10.0</max>
            <resolution>0.01</resolution>
          </range>
        </lidar>
        <alwaysOn>1</alwaysOn>
        <visualize>true</visualize>
      </sensor>
    </link>
    <joint name="lidar_joint" type="fixed">
      <parent>chassis</parent>
      <child>lidar</child>
    </joint>

    <!-- IMU sensor (new) -->
    <link name="imu_link">
      <!-- Adjust the pose relative to chassis as needed -->
      <pose relative_to="chassis">-0.15 0 0.32 0 0 0</pose>
      <sensor name="imu_sensor" type="imu">
        <always_on>1</always_on>
        <update_rate>50</update_rate>
        <visualize>true</visualize>
        <topic>imu</topic>
        <gz_frame_id>imu</gz_frame_id>
      </sensor>
    </link>
    <joint name="imu_joint" type="fixed">
      <parent>chassis</parent>
      <child>imu_link</child>
      <pose>0 0 0 0 0 0</pose>
    </joint>

    <!-- ======================== JOINTS ======================== -->
    <!-- Left wheel joint -->
    <joint name="left_wheel_joint" type="revolute">
      <parent>chassis</parent>
      <child>left_wheel</child>
      <axis>
        <xyz>0 0 -1</xyz>
      </axis>
    </joint>

    <!-- Right wheel joint -->
    <joint name="right_wheel_joint" type="revolute">
      <parent>chassis</parent>
      <child>right_wheel</child>
      <axis>
        <xyz>0 0 1</xyz>
      </axis>
    </joint>

    <!-- Left front wheel joint -->
    <joint name="left_front_wheel_joint" type="revolute">
      <parent>chassis</parent>
      <child>left_front_wheel</child>
      <axis>
        <xyz>0 0 -1</xyz>
      </axis>
    </joint>

    <!-- Right front wheel joint -->
    <joint name="right_front_wheel_joint" type="revolute">
      <parent>chassis</parent>
      <child>right_front_wheel</child>
      <axis>
        <xyz>0 0 1</xyz>
      </axis>
    </joint>

    <!-- ======================== DIFF DRIVE & KEYBOARD PLUGINS ======================== -->
    <plugin filename="gz-sim-diff-drive-system" name="gz::sim::systems::DiffDrive">
      <!-- Left-side wheel joints -->
      <left_joint>left_wheel_joint</left_joint>
      <left_joint>left_front_wheel_joint</left_joint>
      <!-- Right-side wheel joints -->
      <right_joint>right_wheel_joint</right_joint>
      <right_joint>right_front_wheel_joint</right_joint>
      <wheel_separation>0.586</wheel_separation>
      <wheel_radius>0.161</wheel_radius>
      <min_velocity>-1.0</min_velocity>
      <max_velocity>1.0</max_velocity>
      <min_acceleration>-3.0</min_acceleration>
      <max_acceleration>3.0</max_acceleration>
      <odom_publish_frequency>30</odom_publish_frequency>
      <odom_topic>odom</odom_topic>
      <tf_topic>tf</tf_topic>
      <frame_id>odom</frame_id>
      <child_frame_id>base_link</child_frame_id>
      <topic>cmd_vel</topic>
    </plugin>

    <!-- Keyboard controls: arrow keys to publish Twist commands -->
    <plugin filename="gz-sim-triggered-publisher-system" name="gz::sim::systems::TriggeredPublisher">
      <input type="gz.msgs.Int32" topic="/keyboard/keypress">
        <match field="data">16777235</match>
      </input>
      <output type="gz.msgs.Twist" topic="/cmd_vel">
        linear: {x: 0.0}, angular: {z: -0.5}
      </output>
    </plugin>

    <plugin filename="gz-sim-triggered-publisher-system" name="gz::sim::systems::TriggeredPublisher">
      <input type="gz.msgs.Int32" topic="/keyboard/keypress">
        <match field="data">16777237</match>
      </input>
      <output type="gz.msgs.Twist" topic="/cmd_vel">
        linear: {x: 0.0}, angular: {z: 0.5}
      </output>
    </plugin>

    <plugin filename="gz-sim-triggered-publisher-system" name="gz::sim::systems::TriggeredPublisher">
      <input type="gz.msgs.Int32" topic="/keyboard/keypress">
        <match field="data">16777234</match>
      </input>
      <output type="gz.msgs.Twist" topic="/cmd_vel">
        linear: {x: -0.5}, angular: {z: 0.0}
      </output>
    </plugin>

    <plugin filename="gz-sim-triggered-publisher-system" name="gz::sim::systems::TriggeredPublisher">
      <input type="gz.msgs.Int32" topic="/keyboard/keypress">
        <match field="data">16777236</match>
      </input>
      <output type="gz.msgs.Twist" topic="/cmd_vel">
        linear: {x: 0.5}, angular: {z: 0.0}
      </output>
    </plugin>

    <plugin filename="gz-sim-triggered-publisher-system" name="gz::sim::systems::TriggeredPublisher">
      <input type="gz.msgs.Int32" topic="/keyboard/keypress">
        <match field="data">48</match>
      </input>
      <output type="gz.msgs.Twist" topic="/cmd_vel">
        linear: {x: 0.0}, angular: {z: 0.0}
      </output>
    </plugin>

    <plugin 
      filename="gz-sim-joint-state-publisher-system"
      name="gz::sim::systems::JointStatePublisher">
    </plugin>



  </model>
</sdf>
