<?xml version="1.0"?>
<sdf version="1.10">
  <model name="robot_car" canonical_link='base_link'>
    <!-- ======================== LINKS ======================== -->
    <!-- Chassis -->
    <link name="base_link">
      <pose relative_to='__model__'>0 0 0 0 0 0</pose>
    </link>

    <!-- Chassis -->
    <link name="chassis">
      <pose relative_to="base_link">0.0 0.0 0.5 0 0 0</pose>
      <!-- Inertial (example for 2.0 kg) -->
      <inertial>
        <mass>1.9</mass>
        <inertia>
          <ixx>0.0794</ixx>
          <ixy>0.0</ixy>
          <ixz>0.0</ixz>
          <iyy>0.0768</iyy>
          <iyz>0.0</iyz>
          <izz>0.0678</izz>
        </inertia>
      </inertial>
      <!-- Collision geometry (with demo friction settings) -->
      <collision name="chassis_collision">
        <geometry>
          <box>
            <size>0.586 0.202 0.173</size>
          </box>
        </geometry>
        <surface>
          <friction>
            <ode>
              <mu>50</mu>
            </ode>
            <bullet>
              <friction>1</friction>
              <rolling_friction>0.1</rolling_friction>
            </bullet>
          </friction>
        </surface>
      </collision>
      <!-- Visual geometry (unchanged) -->
      <visual name="chassis_visual">
        <pose>0 0 -0.62 1.5707 0 -1.5707</pose>
        <geometry>
          <mesh>
            <uri>meshes/f1.obj</uri>
            <scale>1.0 1.0 1.0</scale>
          </mesh>
        </geometry>
      </visual>
    </link>
    <link name='base_footprint'>
      <pose relative_to='base_link'>0 0 0 0 0 0</pose>
    </link>
    <joint name='base_footprint_joint' type='fixed'>
      <parent>base_link</parent>
      <child>base_footprint</child>
    </joint>
    <!-- Rear Wheels -->
    <link name="rear_left_wheel">
      <pose relative_to="chassis">-0.182 0.141 -0.040 -1.5707 0 0</pose>
      <inertial>
        <mass>0.07</mass>
        <inertia>
          <ixx>0.00545</ixx>
          <ixy>0.0</ixy>
          <ixz>0.0</ixz>
          <iyy>0.00545</iyy>
          <iyz>0.0</iyz>
          <izz>0.00919</izz>
        </inertia>
      </inertial>
      <collision name="left_wheel_collision">
        <geometry>
          <cylinder>
            <radius>0.1</radius>
            <length>0.07</length>
          </cylinder>
        </geometry>
        <surface>
          <friction>
            <ode>
              <mu>0.5</mu>
              <mu2>1.0</mu2>
              <fdir1>0 0 1</fdir1>
            </ode>
            <bullet>
              <friction>0.5</friction>
              <friction2>1</friction2>
              <rolling_friction>0.1</rolling_friction>
            </bullet>
          </friction>
        </surface>
      </collision>
    </link>

    <link name="rear_right_wheel">
      <pose relative_to="chassis">-0.182 -0.141 -0.040 -1.5707 0 0</pose>
      <inertial>
        <mass>0.07</mass>
        <inertia>
          <ixx>0.00545</ixx>
          <ixy>0.0</ixy>
          <ixz>0.0</ixz>
          <iyy>0.00545</iyy>
          <iyz>0.0</iyz>
          <izz>0.00919</izz>
        </inertia>
      </inertial>
      <collision name="right_wheel_collision">
        <geometry>
          <cylinder>
            <radius>0.1</radius>
            <length>0.07</length>
          </cylinder>
        </geometry>
        <surface>
          <friction>
            <ode>
              <mu>0.5</mu>
              <mu2>1.0</mu2>
              <fdir1>0 0 1</fdir1>
            </ode>
            <bullet>
              <friction>0.5</friction>
              <friction2>1</friction2>
              <rolling_friction>0.1</rolling_friction>
            </bullet>
          </friction>
        </surface>
      </collision>
    </link>

    <!-- Front Wheels -->
    <link name="left_front_wheel">
      <pose relative_to="chassis">0.182 0.141 -0.040 -1.5707 0 0</pose>
      <inertial>
        <mass>0.07</mass>
        <inertia>
          <ixx>0.00545</ixx>
          <ixy>0.0</ixy>
          <ixz>0.0</ixz>
          <iyy>0.00545</iyy>
          <iyz>0.0</iyz>
          <izz>0.00919</izz>
        </inertia>
      </inertial>
      <collision name="left_front_wheel_collision">
        <geometry>
          <cylinder>
            <radius>0.1</radius>
            <length>0.07</length>
          </cylinder>
        </geometry>
        <surface>
          <friction>
            <ode>
              <mu>0.5</mu>
              <mu2>1.0</mu2>
              <fdir1>0 0 1</fdir1>
            </ode>
            <bullet>
              <friction>0.5</friction>
              <friction2>1</friction2>
              <rolling_friction>0.1</rolling_friction>
            </bullet>
          </friction>
        </surface>
      </collision>
    </link>

    <link name="right_front_wheel">
      <pose relative_to="chassis">0.182 -0.141 -0.040 -1.5707 0 0</pose>
      <inertial>
        <mass>0.07</mass>
        <inertia>
          <ixx>0.00545</ixx>
          <ixy>0.0</ixy>
          <ixz>0.0</ixz>
          <iyy>0.00545</iyy>
          <iyz>0.0</iyz>
          <izz>0.00919</izz>
        </inertia>
      </inertial>
      <collision name="right_front_wheel_collision">
        <geometry>
          <cylinder>
            <radius>0.1</radius>
            <length>0.07</length>
          </cylinder>
        </geometry>
        <surface>
          <friction>
            <ode>
              <mu>0.5</mu>
              <mu2>1.0</mu2>
              <fdir1>0 0 1</fdir1>
            </ode>
            <bullet>
              <friction>0.5</friction>
              <friction2>1</friction2>
              <rolling_friction>0.1</rolling_friction>
            </bullet>
          </friction>
        </surface>
      </collision>
    </link>

    <!-- ======================== JOINTS ======================== -->
    <!-- Steering links & joints for front wheels -->
    <link name="front_left_wheel_steering_link">
      <pose relative_to="chassis">0.182 0.141 -0.040 0 0 0</pose>
      <inertial>
        <mass>0.01</mass>
        <inertia>
          <ixx>0.00153</ixx>
          <iyy>0.0025</iyy>
          <izz>0.00153</izz>
        </inertia>
      </inertial>
    </link>

    <link name="front_right_wheel_steering_link">
      <pose relative_to="chassis">0.182 -0.141 -0.040 0 0 0</pose>
      <inertial>
        <mass>0.01</mass>
        <inertia>
          <ixx>0.00153</ixx>
          <iyy>0.0025</iyy>
          <izz>0.00153</izz>
        </inertia>
      </inertial>
    </link>

    <joint name="front_left_wheel_steering_joint" type="revolute">
      <child>front_left_wheel_steering_link</child>
      <parent>chassis</parent>
      <pose>0 0 0 0 0 0</pose>
      <axis>
        <xyz>0 0 1</xyz>
        <limit>
          <lower>-0.6</lower>
          <upper>0.6</upper>
          <velocity>1.0</velocity>
          <effort>25</effort>
        </limit>
        <use_parent_model_frame>1</use_parent_model_frame>
      </axis>
    </joint>

    <joint name="front_right_wheel_steering_joint" type="revolute">
      <parent>chassis</parent>
      <child>front_right_wheel_steering_link</child>
      <pose>0 0 0 0 0 0</pose>
      <axis>
        <xyz>0 0 1</xyz>
        <limit>
          <lower>-0.6</lower>
          <upper>0.6</upper>
          <velocity>1.0</velocity>
          <effort>25</effort>
        </limit>
        <use_parent_model_frame>1</use_parent_model_frame>
      </axis>
    </joint>

    <!-- Front wheel joints: attach wheels to steering links -->
    <joint name="front_left_wheel_joint" type="revolute">
      <parent>front_left_wheel_steering_link</parent>
      <child>left_front_wheel</child>
      <pose>0 0 0 0 0 0</pose>
      <axis>
        <xyz>0 0 1</xyz>
        <limit>
          <lower>-1.79769e+308</lower>
          <upper>1.79769e+308</upper>
        </limit>
      </axis>
    </joint>

    <!-- Corrected: Use the existing link name "right_front_wheel" -->
    <joint name="front_right_wheel_joint" type="revolute">
      <parent>front_right_wheel_steering_link</parent>
      <child>right_front_wheel</child>
      <pose>0 0 0 0 0 0</pose>
      <axis>
        <xyz>0 0 1</xyz>
        <limit>
          <lower>-1.79769e+308</lower>
          <upper>1.79769e+308</upper>
        </limit>
      </axis>
    </joint>

    <!-- Rear wheel joints: attach rear wheels directly to chassis -->
    <joint name="rear_left_wheel_joint" type="revolute">
      <parent>chassis</parent>
      <child>rear_left_wheel</child>
      <pose>0 0 0 0 0 0</pose>
      <axis>
        <xyz>0 0 1</xyz>
        <limit>
          <lower>-1.79769e+308</lower>
          <upper>1.79769e+308</upper>
        </limit>
      </axis>
      <parent>chassis</parent>
      <child>rear_left_wheel_joint</child>
    </joint>

    <joint name="rear_right_wheel_joint" type="revolute">
      <parent>chassis</parent>
      <child>rear_right_wheel</child>
      <pose>0 0 0 0 0 0</pose>
      <axis>
        <xyz>0 0 1</xyz>
        <limit>
          <lower>-1.79769e+308</lower>
          <upper>1.79769e+308</upper>
        </limit>
      </axis>
    </joint>

    <!-- ======================== ACKERMANN STEERING PLUGIN ======================== -->
    <plugin filename="gz-sim-ackermann-steering-system" name="gz::sim::systems::AckermannSteering">
      <left_joint>front_left_wheel_joint</left_joint>
      <left_joint>rear_left_wheel_joint</left_joint>
      <right_joint>front_right_wheel_joint</right_joint>
      <right_joint>rear_right_wheel_joint</right_joint>
      <left_steering_joint>front_left_wheel_steering_joint</left_steering_joint>
      <right_steering_joint>front_right_wheel_steering_joint</right_steering_joint>
      <!-- Updated parameters for your small vehicle: -->
      <kingpin_width>0.282</kingpin_width>
      <steering_limit>0.5</steering_limit>
      <wheel_base>0.364</wheel_base>
      <wheel_separation>0.282</wheel_separation>
      <wheel_radius>0.1</wheel_radius>
      <min_velocity>-1</min_velocity>
      <max_velocity>1</max_velocity>
      <min_acceleration>-3</min_acceleration>
      <max_acceleration>3</max_acceleration>     
      <topic>cmd_vel</topic>
      <odom_publish_frequency>30</odom_publish_frequency>
      <odom_topic>odom</odom_topic>
      <tf_topic>tf</tf_topic>
      <frame_id>odom</frame_id>
      <child_frame_id>base_link</child_frame_id>    </plugin>

      <!-- Keyboard Triggered Publishers -->
      <!-- Moving Forward -->
    <plugin filename="gz-sim-triggered-publisher-system" name="gz::sim::systems::TriggeredPublisher">
      <input type="gz.msgs.Int32" topic="/keyboard/keypress">
        <match field="data">16777235</match>
      </input>
      <output type="gz.msgs.Twist" topic="/cmd_vel">
        linear: {x: 0.5}, angular: {z: 0.0}
      </output>
    </plugin>

    <!-- Moving Backward -->
    <plugin filename="gz-sim-triggered-publisher-system" name="gz::sim::systems::TriggeredPublisher">
      <input type="gz.msgs.Int32" topic="/keyboard/keypress">
        <match field="data">16777237</match>
      </input>
      <output type="gz.msgs.Twist" topic="/cmd_vel">
        linear: {x: -0.5}, angular: {z: 0.0}
      </output>
    </plugin>

    <!-- Moving Left -->
    <plugin filename="gz-sim-triggered-publisher-system" name="gz::sim::systems::TriggeredPublisher">
      <input type="gz.msgs.Int32" topic="/keyboard/keypress">
        <match field="data">16777234</match>
      </input>
      <output type="gz.msgs.Twist" topic="/cmd_vel">
        linear: {x: 0.5}, angular: {z: 0.5}
      </output>
    </plugin>

    <!-- Moving Right -->
    <plugin filename="gz-sim-triggered-publisher-system" name="gz::sim::systems::TriggeredPublisher">
      <input type="gz.msgs.Int32" topic="/keyboard/keypress">
        <match field="data">16777236</match>
      </input>
      <output type="gz.msgs.Twist" topic="/cmd_vel">
        linear: {x: 0.5}, angular: {z: -0.5}
      </output>
    </plugin>

    <!-- Stopping -->
    <plugin filename="gz-sim-triggered-publisher-system" name="gz::sim::systems::TriggeredPublisher">
      <input type="gz.msgs.Int32" topic="/keyboard/keypress">
        <match field="data">48</match>
      </input>
      <output type="gz.msgs.Twist" topic="/cmd_vel">
        linear: {x: 0.0}, angular: {z: 0.0}
      </output>
    </plugin>
    <!-- ======================== SENSORS (Mounted on Top & Front) ======================== -->
    <link name="camera_body">
      <pose relative_to="chassis">0.3 0 0.05 0 0 0</pose>
      <inertial>
        <mass>0.1</mass>
        <inertia>
          <ixx>0.000166667</ixx>
          <iyy>0.000166667</iyy>
          <izz>0.000166667</izz>
        </inertia>
      </inertial>
      <collision name="collision">
        <geometry>
          <box>
            <size>0.05 0.05 0.05</size>
          </box>
        </geometry>
      </collision>
      <visual name="visual">
        <geometry>
          <box>
            <size>0.05 0.05 0.05</size>
          </box>
        </geometry>
      </visual>
      <sensor name="camera" type="camera">
        <camera>
          <optical_frame_id>camera</optical_frame_id>
          <horizontal_fov>1.047</horizontal_fov>
          <image>
            <width>320</width>
            <height>240</height>
          </image>
          <clip>
            <near>0.1</near>
            <far>100</far>
          </clip>
        </camera>
        <always_on>1</always_on>
        <update_rate>30</update_rate>
        <visualize>true</visualize>
        <topic>camera</topic>
      </sensor>
    </link>
    <link name = 'camera'>
      <pose relative_to='camera_body'>0.01 0 0 1.5708 3.141 1.5707</pose>
    </link>
    <joint name='camera_optical_joint' type='fixed'>
      <parent>camera_body</parent>
      <child>camera</child>
    </joint>
    <joint name="camera_joint" type="fixed">
      <parent>chassis</parent>
      <child>camera_body</child>
    </joint>

    <link name="gps_link">
      <pose relative_to="chassis">0 0 0.1 0 0 0</pose>
      <inertial>
        <mass>0.1</mass>
        <inertia>
          <ixx>0.000166667</ixx>
          <iyy>0.000166667</iyy>
          <izz>0.000166667</izz>
        </inertia>
      </inertial>
      <collision name="collision">
        <geometry>
          <box>
            <size>0.01 0.01 0.01</size>
          </box>
        </geometry>
      </collision>
      <visual name="visual">
        <geometry>
          <box>
            <size>0.01 0.01 0.01</size>
          </box>
        </geometry>
      </visual>
      <sensor name="navsat_sensor" type="navsat">
        <always_on>1</always_on>
        <update_rate>30</update_rate>
        <topic>navsat</topic>
        <gz_frame_id>gps</gz_frame_id>
      </sensor>
    </link>
    <joint name="gps_joint" type="fixed">
      <parent>chassis</parent>
      <child>gps_link</child>
    </joint>

    <!-- IMU sensor (new) -->
    <link name="imu_link">
      <!-- Adjust the pose relative to chassis as needed -->
      <pose relative_to="chassis">-0.15 0 0.32 0 0 0</pose>
      <sensor name="imu_sensor" type="imu">
        <always_on>1</always_on>
        <update_rate>50</update_rate>
        <visualize>true</visualize>
        <topic>imu</topic>
        <gz_frame_id>imu</gz_frame_id>
        <imu>
          <!-- Noise parameters or biases can be added here if desired -->
          <angular_velocity>
            <x>0.0</x>
            <y>0.0</y>
            <z>0.0</z>
          </angular_velocity>
          <linear_acceleration>
            <x>0.0</x>
            <y>0.0</y>
            <z>0.0</z>
          </linear_acceleration>
          <orientation>
            <x>0.0</x>
            <y>0.0</y>
            <z>0.0</z>
            <w>1.0</w>
          </orientation>
        </imu>
      </sensor>
    </link>
    <joint name="imu_joint" type="fixed">
      <parent>chassis</parent>
      <child>imu_link</child>
      <pose>0 0 0 0 0 0</pose>
    </joint>


    <link name="lidar">
      <pose relative_to="chassis">0.15 0 0.1 0 0 0</pose>
      <inertial>
        <mass>0.01</mass>
        <inertia>
          <ixx>0.000166667</ixx>
          <iyy>0.000166667</iyy>
          <izz>0.000166667</izz>
        </inertia>
      </inertial>
      <collision name="collision">
        <geometry>
          <box>
            <size>0.01 0.01 0.01</size>
          </box>
        </geometry>
      </collision>
      <visual name="visual">
        <geometry>
          <cylinder>
            <radius>0.05</radius>
            <length>0.05</length>
          </cylinder>
        </geometry>
      </visual>
      <sensor name="gpu_lidar" type="gpu_lidar">
        <pose relative_to="lidar">0 0 0.0 0 0 0</pose>
        <topic>scan</topic>
        <gz_frame_id>lidar</gz_frame_id>
        <update_rate>10</update_rate>
        <lidar>
          <scan>
            <horizontal>
              <samples>1081</samples>
              <resolution>1</resolution>
              <min_angle>-2.356</min_angle>
              <max_angle>2.356</max_angle>
            </horizontal>
          </scan>
          <range>
            <min>0.05</min>
            <max>10.0</max>
            <resolution>0.01</resolution>
          </range>
        </lidar>
        <alwaysOn>1</alwaysOn>
        <visualize>true</visualize>
      </sensor>
    </link>
    <joint name="lidar_joint" type="fixed">
      <parent>chassis</parent>
      <child>lidar</child>
    </joint>  
  </model>
</sdf>
